Workbook

Sheet Start here
A1: Bioprocess Phase Planner
A2: Predicts cell density, metabolites, volumes, medium use and biomass for a process built from phases.
A4: HOW TO USE – 5 steps
A5: 1. 1 Setup → vessel volume, working volume, seeding density and the metabolite / media table.
A6: 2. 2 Phases → choose the number of phases (1–6), then for each phase pick its type and duration.
A7: 3. Fill only the yellow cells of each phase row – cells that do not apply to that type turn grey:
A8: Batch → target cell density at the end of the phase
A9: Fed-batch → target cell density + a feed regime (defined on 3 Feed regimes)
A10: Continuous → feed (perfusion) rate and bleed rate – suggestions are shown next to them
A11: 4. 3 Feed regimes → daily additions (% of the initial working volume) for fed-batch phases.
A12: 5. Results → key numbers, per-phase table, checks and charts. The 'Check' column on 2 Phases tells you what is missing.
A14: Colours: yellow = input · grey = not needed · green = OK · red = needs attention
... A22: Wet biomass = VCC/1E6 × (g/L at 1E6 cells/mL). Cells produced = cells at end + cells removed by bleed − cells inoculated.

Sheet 1 Setup
A1: 1 · Setup
A2: Process settings and metabolites. Yellow cells are inputs.
A3: Setting | B3: Value | C3: Unit | D3: Note
A4: Vessel volume (total) | B4: 2 | C4: L | D4: Placeholder – replace with your vessel
A5: Initial working volume | B5: 1 | C5: L | D5: =IF(B5>=B4,"⚠ must be below the vessel volume","OK") -> OK
A6: Seeding density (day 0) | B6: 800000 | C6: cells/mL
A7: Wet biomass at 1E6 cells/mL | B7: 2 | C7: g/L | D7: Assumption – wet biomass scales with cell density
A9: Metabolite | B9: Consumed / produced | C9: q (× 1E-11 mmol/cell/h) | D9: Limit (mM) | E9: Batch medium (mM) | F9: Fed-batch feed (mM) | G9: Perfusion medium (mM) | H9: sign (auto) | I9: Note
A10: Glucose | B10: consumed | C10: 7.9 | D10: 5 | E10: 25 | F10: 250 | G10: 25 | H10: =IF(B10="consumed",-1,1) -> -1 | I10: Limit = minimum to keep
A11: Lactate | B11: produced | C11: 8.6 | D11: 20 | E11: 0 | F11: 0 | G11: 0 | H11: =IF(B11="consumed",-1,1) -> 1 | I11: Limit = maximum tolerated
A12: Glutamine | B12: consumed | D12: 0.5 | H12: =IF(B12="consumed",-1,1) -> -1 | I12: Fill when known
A13: Glutamate | B13: consumed | D13: 0.5 | H13: =IF(B13="consumed",-1,1) -> -1 | I13: Switch to 'produced' if it accumulates
A14: Ammonia | B14: produced | D14: 5 | F14: 0 | G14: 0 | H14: =IF(B14="consumed",-1,1) -> 1 | I14: Fill q and batch medium when known
A16: Limit: a consumed metabolite must stay ABOVE its limit, a produced one BELOW it. Leave cells blank if unknown.

Sheet 2 Phases
A1: 2 · Phases
A2: Pick the number of phases, then a type and duration per phase. Fill the yellow cells; grey cells are not needed for that type. 'Check' tells you what is missing.
A4: Number of phases | B4: 3 | C4: Total duration (days) | D4: =MAX(M7:M12) -> 14 | E4: =IF(D4>120,"⚠ max 120 days","")
A6: # | B6: Used? | C6: Phase type | D6: Duration (days) | E6: Target VCC at end (cells/mL) Batch · Fed-batch | F6: Feed regime Fed-batch | G6: Feed rate (VVD) Continuous | H6: Bleed rate (VVD) Continuous | I6: Growth rate override (1/day) Continuous · optional | J6: What to fill | K6: Check | L6: Start day | M6: End day | N6: Start VCC (cells/mL) | O6: End VCC (cells/mL) | P6: Growth rate (1/day) | Q6: Suggested bleed – holds VCC (VVD) | R6: Suggested min. feed rate (VVD) | S6: Working volume at end (L)
A7: 1 | B7: =IF(A7<=VALUE($B$4),"yes","—") -> yes | C7: Batch | D7: 2 | E7: 2370000 | J7: =IF(B7<>"yes","(not used)",IF(C7="Batch","duration + target VCC",IF(C7="Fed-batch","duration + target VCC + feed regime",IF(C7="Continuous","duration + feed rate + bleed rate","choose a phase type")))) -> duration + target VCC | K7: =IF(B7<>"yes","—",IF(C7="","⚠ choose phase type",IF(N(D7)<=0,"⚠ enter duration",IF(D7<>INT(D7),"⚠ whole days only",IF(AND(C7<>"Continuous",E7=""),"⚠ enter target VCC",IF(AND(C7="Fed-batch",F7=""),"⚠ choose feed regime",IF(AND(C7="Continuous",OR(G7="",H7="")),"⚠ enter feed and bleed rate",IF(AND(C7="Continuous",N(G7)<N(H7)),"⚠ feed rate below bleed rate",IF(AND(C7="Continuous",P7=""),"⚠ no growth rate – enter one","OK"))))))))) -> OK | L7: =IF(B7="yes",0,"") -> 0 | M7: =IF(B7="yes",L7+N(D7),"") -> 2 | N7: =IF(B7="yes",'1 Setup'!$B$6,"") -> 800000 | O7: =IF(B7<>"yes","",IFERROR(IF(C7="Continuous",N7*EXP((P7-N(H7))*N(D7)),IF(E7="",N7,E7)),"")) -> 2370000 | P7: =IF(B7<>"yes","",IF(C7="Continuous",IF(I7<>"",I7,""),IFERROR(LN(E7/N7)/D7,""))) -> 0.54301675 | Q7: =IF(AND(B7="yes",C7="Continuous"),P7,"") | R7: =IF(AND(B7="yes",C7="Continuous"),IFERROR(MAX(Q7,IF(AND(ISNUMBER('1 Setup'!$C$10),ISNUMBER('1 Setup'!$G$10),ISNUMBER('1 Setup'!$D$10),'1 Setup'!$H$10*('1 Setup'!$D$10-'1 Setup'!$G$10)>0),'1 Setup'!$C$10*MAX(N7,O7)*0.00000024/ABS('1 Setup'!$D$10-'1 Setup'!$G$10),0),IF(AND(ISNUMBER('1 Setup'!$C$11),ISNUMBER('1 Setup'!$G$11),ISNUMBER('1 Setup'!$D$11),'1 Setup'!$H$11*('1 Setup'!$D$11-'1 Setup'!$G$11)>0),'1 Setup'!$C$11*MAX(N7,O7)*0.00000024/ABS('1 Setup'!$D$11-'1 Setup'!$G$11),0),IF(AND(ISNUMBER('1 Setup'!$C$12),ISNUMBER('1 Setup'!$G$12),ISNUMBER('1 Setup'!$D$12),'1 Setup'!$H$12*('1 Setup'!$D$12-'1 Setup'!$G$12)>0),'1 Setup'!$C$12*MAX(N7,O7)*0.00000024/ABS('1 Setup'!$D$12-'1 Setup'!$G$12),0),IF(AND(ISNUMBER('1 Setup'!$C$13),ISNUMBER('1 Setup'!$G$13),ISNUMBER('1 Setup'!$D$13),'1 Setup'!$H$13*('1 Setup'!$D$13-'1 Setup'!$G$13)>0),'1 Setup'!$C$13*MAX(N7,O7)*0.00000024/ABS('1 Setup'!$D$13-'1 Setup'!$G$13),0),IF(AND(ISNUMBER('1 Setup'!$C$14),ISNUMBER('1 Setup'!$G$14),ISNUMBER('1 Setup'!$D$14),'1 Setup'!$H$14*('1 Setup'!$D$14-'1 Setup'!$G$14)>0),'1 Setup'!$C$14*MAX(N7,O7)*0.00000024/ABS('1 Setup'!$D$14-'1 Setup'!$G$14),0)),""),"") | S7: =IF(B7<>"yes","",IFERROR(INDEX(Calculation!$G$6:$G$126,MATCH(M7,Calculation!$A$6:$A$126,0)),"")) -> 1
A8: 2 | B8: =IF(A8<=VALUE($B$4),"yes","—") -> yes | C8: Fed-batch | D8: 2 | E8: 7000000 | F8: Regime A | J8: =IF(B8<>"yes","(not used)",IF(C8="Batch","duration + target VCC",IF(C8="Fed-batch","duration + target VCC + feed regime",IF(C8="Continuous","duration + feed rate + bleed rate","choose a phase type")))) -> duration + target VCC + feed regime | K8: =IF(B8<>"yes","—",IF(C8="","⚠ choose phase type",IF(N(D8)<=0,"⚠ enter duration",IF(D8<>INT(D8),"⚠ whole days only",IF(AND(C8<>"Continuous",E8=""),"⚠ enter target VCC",IF(AND(C8="Fed-batch",F8=""),"⚠ choose feed regime",IF(AND(C8="Continuous",OR(G8="",H8="")),"⚠ enter feed and bleed rate",IF(AND(C8="Continuous",N(G8)<N(H8)),"⚠ feed rate below bleed rate",IF(AND(C8="Continuous",P8=""),"⚠ no growth rate – enter one","OK"))))))))) -> OK | L8: =IF(B8="yes",M7,"") -> 2 | M8: =IF(B8="yes",L8+N(D8),"") -> 4 | N8: =IF(B8="yes",O7,"") -> 2370000 | O8: =IF(B8<>"yes","",IFERROR(IF(C8="Continuous",N8*EXP((P8-N(H8))*N(D8)),IF(E8="",N8,E8)),"")) -> 7000000 | P8: =IF(B8<>"yes","",IF(C8="Continuous",IF(I8<>"",I8,P7),IFERROR(LN(E8/N8)/D8,""))) -> 0.5415101 | Q8: =IF(AND(B8="yes",C8="Continuous"),P8,"") | R8: =IF(AND(B8="yes",C8="Continuous"),IFERROR(MAX(Q8,IF(AND(ISNUMBER('1 Setup'!$C$10),ISNUMBER('1 Setup'!$G$10),ISNUMBER('1 Setup'!$D$10),'1 Setup'!$H$10*('1 Setup'!$D$10-'1 Setup'!$G$10)>0),'1 Setup'!$C$10*MAX(N8,O8)*0.00000024/ABS('1 Setup'!$D$10-'1 Setup'!$G$10),0),IF(AND(ISNUMBER('1 Setup'!$C$11),ISNUMBER('1 Setup'!$G$11),ISNUMBER('1 Setup'!$D$11),'1 Setup'!$H$11*('1 Setup'!$D$11-'1 Setup'!$G$11)>0),'1 Setup'!$C$11*MAX(N8,O8)*0.00000024/ABS('1 Setup'!$D$11-'1 Setup'!$G$11),0),IF(AND(ISNUMBER('1 Setup'!$C$12),ISNUMBER('1 Setup'!$G$12),ISNUMBER('1 Setup'!$D$12),'1 Setup'!$H$12*('1 Setup'!$D$12-'1 Setup'!$G$12)>0),'1 Setup'!$C$12*MAX(N8,O8)*0.00000024/ABS('1 Setup'!$D$12-'1 Setup'!$G$12),0),IF(AND(ISNUMBER('1 Setup'!$C$13),ISNUMBER('1 Setup'!$G$13),ISNUMBER('1 Setup'!$D$13),'1 Setup'!$H$13*('1 Setup'!$D$13-'1 Setup'!$G$13)>0),'1 Setup'!$C$13*MAX(N8,O8)*0.00000024/ABS('1 Setup'!$D$13-'1 Setup'!$G$13),0),IF(AND(ISNUMBER('1 Setup'!$C$14),ISNUMBER('1 Setup'!$G$14),ISNUMBER('1 Setup'!$D$14),'1 Setup'!$H$14*('1 Setup'!$D$14-'1 Setup'!$G$14)>0),'1 Setup'!$C$14*MAX(N8,O8)*0.00000024/ABS('1 Setup'!$D$14-'1 Setup'!$G$14),0)),""),"") | S8: =IF(B8<>"yes","",IFERROR(INDEX(Calculation!$G$6:$G$126,MATCH(M8,Calculation!$A$6:$A$126,0)),"")) -> 1.06
A9: 3 | B9: =IF(A9<=VALUE($B$4),"yes","—") -> yes | C9: Continuous | D9: 10 | G9: =R9 -> 0.7224 | H9: =Q9 -> 0.5415101 | J9: =IF(B9<>"yes","(not used)",IF(C9="Batch","duration + target VCC",IF(C9="Fed-batch","duration + target VCC + feed regime",IF(C9="Continuous","duration + feed rate + bleed rate","choose a phase type")))) -> duration + feed rate + bleed rate | K9: =IF(B9<>"yes","—",IF(C9="","⚠ choose phase type",IF(N(D9)<=0,"⚠ enter duration",IF(D9<>INT(D9),"⚠ whole days only",IF(AND(C9<>"Continuous",E9=""),"⚠ enter target VCC",IF(AND(C9="Fed-batch",F9=""),"⚠ choose feed regime",IF(AND(C9="Continuous",OR(G9="",H9="")),"⚠ enter feed and bleed rate",IF(AND(C9="Continuous",N(G9)<N(H9)),"⚠ feed rate below bleed rate",IF(AND(C9="Continuous",P9=""),"⚠ no growth rate – enter one","OK"))))))))) -> OK | L9: =IF(B9="yes",M8,"") -> 4 | M9: =IF(B9="yes",L9+N(D9),"") -> 14 | N9: =IF(B9="yes",O8,"") -> 7000000 | O9: =IF(B9<>"yes","",IFERROR(IF(C9="Continuous",N9*EXP((P9-N(H9))*N(D9)),IF(E9="",N9,E9)),"")) -> 7000000 | P9: =IF(B9<>"yes","",IF(C9="Continuous",IF(I9<>"",I9,P8),IFERROR(LN(E9/N9)/D9,""))) -> 0.5415101 | Q9: =IF(AND(B9="yes",C9="Continuous"),P9,"") -> 0.5415101 | R9: =IF(AND(B9="yes",C9="Continuous"),IFERROR(MAX(Q9,IF(AND(ISNUMBER('1 Setup'!$C$10),ISNUMBER('1 Setup'!$G$10),ISNUMBER('1 Setup'!$D$10),'1 Setup'!$H$10*('1 Setup'!$D$10-'1 Setup'!$G$10)>0),'1 Setup'!$C$10*MAX(N9,O9)*0.00000024/ABS('1 Setup'!$D$10-'1 Setup'!$G$10),0),IF(AND(ISNUMBER('1 Setup'!$C$11),ISNUMBER('1 Setup'!$G$11),ISNUMBER('1 Setup'!$D$11),'1 Setup'!$H$11*('1 Setup'!$D$11-'1 Setup'!$G$11)>0),'1 Setup'!$C$11*MAX(N9,O9)*0.00000024/ABS('1 Setup'!$D$11-'1 Setup'!$G$11),0),IF(AND(ISNUMBER('1 Setup'!$C$12),ISNUMBER('1 Setup'!$G$12),ISNUMBER('1 Setup'!$D$12),'1 Setup'!$H$12*('1 Setup'!$D$12-'1 Setup'!$G$12)>0),'1 Setup'!$C$12*MAX(N9,O9)*0.00000024/ABS('1 Setup'!$D$12-'1 Setup'!$G$12),0),IF(AND(ISNUMBER('1 Setup'!$C$13),ISNUMBER('1 Setup'!$G$13),ISNUMBER('1 Setup'!$D$13),'1 Setup'!$H$13*('1 Setup'!$D$13-'1 Setup'!$G$13)>0),'1 Setup'!$C$13*MAX(N9,O9)*0.00000024/ABS('1 Setup'!$D$13-'1 Setup'!$G$13),0),IF(AND(ISNUMBER('1 Setup'!$C$14),ISNUMBER('1 Setup'!$G$14),ISNUMBER('1 Setup'!$D$14),'1 Setup'!$H$14*('1 Setup'!$D$14-'1 Setup'!$G$14)>0),'1 Setup'!$C$14*MAX(N9,O9)*0.00000024/ABS('1 Setup'!$D$14-'1 Setup'!$G$14),0)),""),"") -> 0.7224 | S9: =IF(B9<>"yes","",IFERROR(INDEX(Calculation!$G$6:$G$126,MATCH(M9,Calculation!$A$6:$A$126,0)),"")) -> 1.06
A10: 4 | B10: =IF(A10<=VALUE($B$4),"yes","—") -> — | J10: =IF(B10<>"yes","(not used)",IF(C10="Batch","duration + target VCC",IF(C10="Fed-batch","duration + target VCC + feed regime",IF(C10="Continuous","duration + feed rate + bleed rate","choose a phase type")))) -> (not used) | K10: =IF(B10<>"yes","—",IF(C10="","⚠ choose phase type",IF(N(D10)<=0,"⚠ enter duration",IF(D10<>INT(D10),"⚠ whole days only",IF(AND(C10<>"Continuous",E10=""),"⚠ enter target VCC",IF(AND(C10="Fed-batch",F10=""),"⚠ choose feed regime",IF(AND(C10="Continuous",OR(G10="",H10="")),"⚠ enter feed and bleed rate",IF(AND(C10="Continuous",N(G10)<N(H10)),"⚠ feed rate below bleed rate",IF(AND(C10="Continuous",P10=""),"⚠ no growth rate – enter one","OK"))))))))) -> — | L10: =IF(B10="yes",M9,"") | M10: =IF(B10="yes",L10+N(D10),"") | N10: =IF(B10="yes",O9,"") | O10: =IF(B10<>"yes","",IFERROR(IF(C10="Continuous",N10*EXP((P10-N(H10))*N(D10)),IF(E10="",N10,E10)),"")) | P10: =IF(B10<>"yes","",IF(C10="Continuous",IF(I10<>"",I10,P9),IFERROR(LN(E10/N10)/D10,""))) | Q10: =IF(AND(B10="yes",C10="Continuous"),P10,"") | R10: =IF(AND(B10="yes",C10="Continuous"),IFERROR(MAX(Q10,IF(AND(ISNUMBER('1 Setup'!$C$10),ISNUMBER('1 Setup'!$G$10),ISNUMBER('1 Setup'!$D$10),'1 Setup'!$H$10*('1 Setup'!$D$10-'1 Setup'!$G$10)>0),'1 Setup'!$C$10*MAX(N10,O10)*0.00000024/ABS('1 Setup'!$D$10-'1 Setup'!$G$10),0),IF(AND(ISNUMBER('1 Setup'!$C$11),ISNUMBER('1 Setup'!$G$11),ISNUMBER('1 Setup'!$D$11),'1 Setup'!$H$11*('1 Setup'!$D$11-'1 Setup'!$G$11)>0),'1 Setup'!$C$11*MAX(N10,O10)*0.00000024/ABS('1 Setup'!$D$11-'1 Setup'!$G$11),0),IF(AND(ISNUMBER('1 Setup'!$C$12),ISNUMBER('1 Setup'!$G$12),ISNUMBER('1 Setup'!$D$12),'1 Setup'!$H$12*('1 Setup'!$D$12-'1 Setup'!$G$12)>0),'1 Setup'!$C$12*MAX(N10,O10)*0.00000024/ABS('1 Setup'!$D$12-'1 Setup'!$G$12),0),IF(AND(ISNUMBER('1 Setup'!$C$13),ISNUMBER('1 Setup'!$G$13),ISNUMBER('1 Setup'!$D$13),'1 Setup'!$H$13*('1 Setup'!$D$13-'1 Setup'!$G$13)>0),'1 Setup'!$C$13*MAX(N10,O10)*0.00000024/ABS('1 Setup'!$D$13-'1 Setup'!$G$13),0),IF(AND(ISNUMBER('1 Setup'!$C$14),ISNUMBER('1 Setup'!$G$14),ISNUMBER('1 Setup'!$D$14),'1 Setup'!$H$14*('1 Setup'!$D$14-'1 Setup'!$G$14)>0),'1 Setup'!$C$14*MAX(N10,O10)*0.00000024/ABS('1 Setup'!$D$14-'1 Setup'!$G$14),0)),""),"") | S10: =IF(B10<>"yes","",IFERROR(INDEX(Calculation!$G$6:$G$126,MATCH(M10,Calculation!$A$6:$A$126,0)),""))
A11: 5 | B11: =IF(A11<=VALUE($B$4),"yes","—") -> — | J11: =IF(B11<>"yes","(not used)",IF(C11="Batch","duration + target VCC",IF(C11="Fed-batch","duration + target VCC + feed regime",IF(C11="Continuous","duration + feed rate + bleed rate","choose a phase type")))) -> (not used) | K11: =IF(B11<>"yes","—",IF(C11="","⚠ choose phase type",IF(N(D11)<=0,"⚠ enter duration",IF(D11<>INT(D11),"⚠ whole days only",IF(AND(C11<>"Continuous",E11=""),"⚠ enter target VCC",IF(AND(C11="Fed-batch",F11=""),"⚠ choose feed regime",IF(AND(C11="Continuous",OR(G11="",H11="")),"⚠ enter feed and bleed rate",IF(AND(C11="Continuous",N(G11)<N(H11)),"⚠ feed rate below bleed rate",IF(AND(C11="Continuous",P11=""),"⚠ no growth rate – enter one","OK"))))))))) -> — | L11: =IF(B11="yes",M10,"") | M11: =IF(B11="yes",L11+N(D11),"") | N11: =IF(B11="yes",O10,"") | O11: =IF(B11<>"yes","",IFERROR(IF(C11="Continuous",N11*EXP((P11-N(H11))*N(D11)),IF(E11="",N11,E11)),"")) | P11: =IF(B11<>"yes","",IF(C11="Continuous",IF(I11<>"",I11,P10),IFERROR(LN(E11/N11)/D11,""))) | Q11: =IF(AND(B11="yes",C11="Continuous"),P11,"") | R11: =IF(AND(B11="yes",C11="Continuous"),IFERROR(MAX(Q11,IF(AND(ISNUMBER('1 Setup'!$C$10),ISNUMBER('1 Setup'!$G$10),ISNUMBER('1 Setup'!$D$10),'1 Setup'!$H$10*('1 Setup'!$D$10-'1 Setup'!$G$10)>0),'1 Setup'!$C$10*MAX(N11,O11)*0.00000024/ABS('1 Setup'!$D$10-'1 Setup'!$G$10),0),IF(AND(ISNUMBER('1 Setup'!$C$11),ISNUMBER('1 Setup'!$G$11),ISNUMBER('1 Setup'!$D$11),'1 Setup'!$H$11*('1 Setup'!$D$11-'1 Setup'!$G$11)>0),'1 Setup'!$C$11*MAX(N11,O11)*0.00000024/ABS('1 Setup'!$D$11-'1 Setup'!$G$11),0),IF(AND(ISNUMBER('1 Setup'!$C$12),ISNUMBER('1 Setup'!$G$12),ISNUMBER('1 Setup'!$D$12),'1 Setup'!$H$12*('1 Setup'!$D$12-'1 Setup'!$G$12)>0),'1 Setup'!$C$12*MAX(N11,O11)*0.00000024/ABS('1 Setup'!$D$12-'1 Setup'!$G$12),0),IF(AND(ISNUMBER('1 Setup'!$C$13),ISNUMBER('1 Setup'!$G$13),ISNUMBER('1 Setup'!$D$13),'1 Setup'!$H$13*('1 Setup'!$D$13-'1 Setup'!$G$13)>0),'1 Setup'!$C$13*MAX(N11,O11)*0.00000024/ABS('1 Setup'!$D$13-'1 Setup'!$G$13),0),IF(AND(ISNUMBER('1 Setup'!$C$14),ISNUMBER('1 Setup'!$G$14),ISNUMBER('1 Setup'!$D$14),'1 Setup'!$H$14*('1 Setup'!$D$14-'1 Setup'!$G$14)>0),'1 Setup'!$C$14*MAX(N11,O11)*0.00000024/ABS('1 Setup'!$D$14-'1 Setup'!$G$14),0)),""),"") | S11: =IF(B11<>"yes","",IFERROR(INDEX(Calculation!$G$6:$G$126,MATCH(M11,Calculation!$A$6:$A$126,0)),""))
A12: 6 | B12: =IF(A12<=VALUE($B$4),"yes","—") -> — | J12: =IF(B12<>"yes","(not used)",IF(C12="Batch","duration + target VCC",IF(C12="Fed-batch","duration + target VCC + feed regime",IF(C12="Continuous","duration + feed rate + bleed rate","choose a phase type")))) -> (not used) | K12: =IF(B12<>"yes","—",IF(C12="","⚠ choose phase type",IF(N(D12)<=0,"⚠ enter duration",IF(D12<>INT(D12),"⚠ whole days only",IF(AND(C12<>"Continuous",E12=""),"⚠ enter target VCC",IF(AND(C12="Fed-batch",F12=""),"⚠ choose feed regime",IF(AND(C12="Continuous",OR(G12="",H12="")),"⚠ enter feed and bleed rate",IF(AND(C12="Continuous",N(G12)<N(H12)),"⚠ feed rate below bleed rate",IF(AND(C12="Continuous",P12=""),"⚠ no growth rate – enter one","OK"))))))))) -> — | L12: =IF(B12="yes",M11,"") | M12: =IF(B12="yes",L12+N(D12),"") | N12: =IF(B12="yes",O11,"") | O12: =IF(B12<>"yes","",IFERROR(IF(C12="Continuous",N12*EXP((P12-N(H12))*N(D12)),IF(E12="",N12,E12)),"")) | P12: =IF(B12<>"yes","",IF(C12="Continuous",IF(I12<>"",I12,P11),IFERROR(LN(E12/N12)/D12,""))) | Q12: =IF(AND(B12="yes",C12="Continuous"),P12,"") | R12: =IF(AND(B12="yes",C12="Continuous"),IFERROR(MAX(Q12,IF(AND(ISNUMBER('1 Setup'!$C$10),ISNUMBER('1 Setup'!$G$10),ISNUMBER('1 Setup'!$D$10),'1 Setup'!$H$10*('1 Setup'!$D$10-'1 Setup'!$G$10)>0),'1 Setup'!$C$10*MAX(N12,O12)*0.00000024/ABS('1 Setup'!$D$10-'1 Setup'!$G$10),0),IF(AND(ISNUMBER('1 Setup'!$C$11),ISNUMBER('1 Setup'!$G$11),ISNUMBER('1 Setup'!$D$11),'1 Setup'!$H$11*('1 Setup'!$D$11-'1 Setup'!$G$11)>0),'1 Setup'!$C$11*MAX(N12,O12)*0.00000024/ABS('1 Setup'!$D$11-'1 Setup'!$G$11),0),IF(AND(ISNUMBER('1 Setup'!$C$12),ISNUMBER('1 Setup'!$G$12),ISNUMBER('1 Setup'!$D$12),'1 Setup'!$H$12*('1 Setup'!$D$12-'1 Setup'!$G$12)>0),'1 Setup'!$C$12*MAX(N12,O12)*0.00000024/ABS('1 Setup'!$D$12-'1 Setup'!$G$12),0),IF(AND(ISNUMBER('1 Setup'!$C$13),ISNUMBER('1 Setup'!$G$13),ISNUMBER('1 Setup'!$D$13),'1 Setup'!$H$13*('1 Setup'!$D$13-'1 Setup'!$G$13)>0),'1 Setup'!$C$13*MAX(N12,O12)*0.00000024/ABS('1 Setup'!$D$13-'1 Setup'!$G$13),0),IF(AND(ISNUMBER('1 Setup'!$C$14),ISNUMBER('1 Setup'!$G$14),ISNUMBER('1 Setup'!$D$14),'1 Setup'!$H$14*('1 Setup'!$D$14-'1 Setup'!$G$14)>0),'1 Setup'!$C$14*MAX(N12,O12)*0.00000024/ABS('1 Setup'!$D$14-'1 Setup'!$G$14),0)),""),"") | S12: =IF(B12<>"yes","",IFERROR(INDEX(Calculation!$G$6:$G$126,MATCH(M12,Calculation!$A$6:$A$126,0)),""))
A14: Feed and bleed rates are in reactor volumes per day (VVD). Default continuous inputs point to the suggestions (columns Q–R) – overwrite them with your own numbers.
A15: Suggested min. feed rate = the larger of the bleed rate and the rate that keeps every metabolite within its limit (using the perfusion medium on 1 Setup).

Sheet 3 Feed regimes
A1: 3 · Feed regimes (for fed-batch phases)
A2: Bolus added at the end of each day of a fed-batch phase, as % of the initial working volume. Composition = 'Fed-batch feed' column on 1 Setup. Day 1 = first day of the phase.
A4: Phase day | B4: Regime A | C4: Regime B | D4: Regime C | E4: Regime D
A5: Description | B5: 3 % on days 1–2 | C5: 2 % every day | D5: 5 % every 2nd day | E5: custom
A6: 1 | B6: 3 | C6: 2
A7: 2 | B7: 3 | C7: 2 | D7: 5
A8: 3 | C8: 2
A9: 4 | C9: 2 | D9: 5
A10: 5 | C10: 2
A11: 6 | C11: 2 | D11: 5
A12: 7 | C12: 2
A13: 8 | C13: 2 | D13: 5
A14: 9 | C14: 2
A15: 10 | C15: 2 | D15: 5
A16: 11 | C16: 2
A17: 12 | C17: 2 | D17: 5
A18: 13 | C18: 2
A19: 14 | C19: 2 | D19: 5
A20: 15 | C20: 2
A21: 16 | C21: 2 | D21: 5
A22: 17 | C22: 2
A23: 18 | C23: 2 | D23: 5
A24: 19 | C24: 2
A25: 20 | C25: 2 | D25: 5
A26: 21 | C26: 2
A27: 22 | C27: 2 | D27: 5
A28: 23 | C28: 2
A29: 24 | C29: 2 | D29: 5
A30: 25 | C30: 2
A31: 26 | C31: 2 | D31: 5
A32: 27 | C32: 2
A33: 28 | C33: 2 | D33: 5
A34: 29 | C34: 2
A35: 30 | C35: 2 | D35: 5
A36: Total over 30 days (% of WV) | B36: =SUM(B6:B35) -> 6 | C36: =SUM(C6:C35) -> 60 | D36: =SUM(D6:D35) -> 75 | E36: =SUM(E6:E35) -> 0

Sheet Results
A1: Results
A2: Everything here is calculated from tabs 1–3.
A3: Key number | B3: Value | C3: Unit | E3: Metabolite | F3: Min (mM) | G3: Max (mM) | H3: Limit (mM) | I3: Status
A4: Total process duration | B4: ='2 Phases'!$D$4 -> 14 | C4: days | E4: Glucose | F4: =IF(COUNT(Calculation!$Q$6:$Q$126)=0,"",MIN(Calculation!$Q$6:$Q$126)) -> 6.6350846 | G4: =IF(COUNT(Calculation!$Q$6:$Q$126)=0,"",MAX(Calculation!$Q$6:$Q$126)) -> 25 | H4: =IF('1 Setup'!$D$10="","",'1 Setup'!$D$10) -> 5 | I4: =IF(OR(F4="",H4=""),"(no data)",IF('1 Setup'!$H$10=-1,IF(F4<H4,"⚠ drops below limit","OK"),IF(G4>H4,"⚠ exceeds limit","OK"))) -> OK
A5: Phase table | B5: =IF(COUNTIF('2 Phases'!$K$7:$K$12,"⚠*")>0,"⚠ check tab 2 Phases","OK") -> OK | E5: Lactate | F5: =IF(COUNT(Calculation!$R$6:$R$126)=0,"",MIN(Calculation!$R$6:$R$126)) -> 0 | G5: =IF(COUNT(Calculation!$R$6:$R$126)=0,"",MAX(Calculation!$R$6:$R$126)) -> 23.818423 | H5: =IF('1 Setup'!$D$11="","",'1 Setup'!$D$11) -> 20 | I5: =IF(OR(F5="",H5=""),"(no data)",IF('1 Setup'!$H$11=-1,IF(F5<H5,"⚠ drops below limit","OK"),IF(G5>H5,"⚠ exceeds limit","OK"))) -> ⚠ exceeds limit
A6: Final cell density | B6: =INDEX(Calculation!$E$6:$E$126,MATCH('2 Phases'!$D$4,Calculation!$A$6:$A$126,0)) -> 7000000 | C6: cells/mL | E6: Glutamine | F6: =IF(COUNT(Calculation!$S$6:$S$126)=0,"",MIN(Calculation!$S$6:$S$126)) | G6: =IF(COUNT(Calculation!$S$6:$S$126)=0,"",MAX(Calculation!$S$6:$S$126)) | H6: =IF('1 Setup'!$D$12="","",'1 Setup'!$D$12) -> 0.5 | I6: =IF(OR(F6="",H6=""),"(no data)",IF('1 Setup'!$H$12=-1,IF(F6<H6,"⚠ drops below limit","OK"),IF(G6>H6,"⚠ exceeds limit","OK"))) -> (no data)
A7: Final working volume | B7: =INDEX(Calculation!$G$6:$G$126,MATCH('2 Phases'!$D$4,Calculation!$A$6:$A$126,0)) -> 1.06 | C7: L | E7: Glutamate | F7: =IF(COUNT(Calculation!$T$6:$T$126)=0,"",MIN(Calculation!$T$6:$T$126)) | G7: =IF(COUNT(Calculation!$T$6:$T$126)=0,"",MAX(Calculation!$T$6:$T$126)) | H7: =IF('1 Setup'!$D$13="","",'1 Setup'!$D$13) -> 0.5 | I7: =IF(OR(F7="",H7=""),"(no data)",IF('1 Setup'!$H$13=-1,IF(F7<H7,"⚠ drops below limit","OK"),IF(G7>H7,"⚠ exceeds limit","OK"))) -> (no data)
A8: Max working volume | B8: =MAX(Calculation!$G$6:$G$126) -> 1.06 | C8: L | E8: Ammonia | F8: =IF(COUNT(Calculation!$U$6:$U$126)=0,"",MIN(Calculation!$U$6:$U$126)) | G8: =IF(COUNT(Calculation!$U$6:$U$126)=0,"",MAX(Calculation!$U$6:$U$126)) | H8: =IF('1 Setup'!$D$14="","",'1 Setup'!$D$14) -> 5 | I8: =IF(OR(F8="",H8=""),"(no data)",IF('1 Setup'!$H$14=-1,IF(F8<H8,"⚠ drops below limit","OK"),IF(G8>H8,"⚠ exceeds limit","OK"))) -> (no data)
A9: Vessel volume | B9: ='1 Setup'!$B$4 -> 2 | C9: L
A10: Volume check | B10: =IF(B8>B9,"⚠ exceeds vessel volume","OK – "&ROUND(B9-B8,2)&" L headspace") -> OK – 0.94 L headspace
A11: Initial fill | B11: ='1 Setup'!$B$5 -> 1 | C11: L | E11: Phase | F11: Type | G11: Start day | H11: End day | I11: Start VCC | J11: End VCC | K11: Fed-batch feed (L) | L11: Perfusion medium (L) | M11: Bleed (L) | N11: Harvest (L) | O11: Cells removed by bleed | P11: Glucose at end (mM) | Q11: Lactate at end (mM) | R11: Check
A12: Fed-batch feed added | B12: =SUM(Calculation!$F$6:$F$126) -> 0.06 | C12: L | E12: =IF('2 Phases'!$B$7<>"yes","",1) -> 1 | F12: =IF('2 Phases'!$B$7<>"yes","",'2 Phases'!$C$7) -> Batch | G12: =IF('2 Phases'!$B$7<>"yes","",'2 Phases'!$L$7) -> 0 | H12: =IF('2 Phases'!$B$7<>"yes","",'2 Phases'!$M$7) -> 2 | I12: =IF('2 Phases'!$B$7<>"yes","",'2 Phases'!$N$7) -> 800000 | J12: =IF('2 Phases'!$B$7<>"yes","",'2 Phases'!$O$7) -> 2370000 | K12: =IF('2 Phases'!$B$7<>"yes","",SUMIF(Calculation!$B$6:$B$126,1,Calculation!$F$6:$F$126)) -> 0 | L12: =IF('2 Phases'!$B$7<>"yes","",SUMIF(Calculation!$B$6:$B$126,1,Calculation!$I$6:$I$126)) -> 0 | M12: =IF('2 Phases'!$B$7<>"yes","",SUMIF(Calculation!$B$6:$B$126,1,Calculation!$J$6:$J$126)) -> 0 | N12: =IF('2 Phases'!$B$7<>"yes","",SUMIF(Calculation!$B$6:$B$126,1,Calculation!$K$6:$K$126)) -> 0 | O12: =IF('2 Phases'!$B$7<>"yes","",SUMIF(Calculation!$B$6:$B$126,1,Calculation!$L$6:$L$126)) -> 0 | P12: =IF('2 Phases'!$B$7<>"yes","",IFERROR(INDEX(Calculation!$Q$6:$Q$126,MATCH('2 Phases'!$M$7,Calculation!$A$6:$A$126,0)),"")) -> 19.384137 | Q12: =IF('2 Phases'!$B$7<>"yes","",IFERROR(INDEX(Calculation!$R$6:$R$126,MATCH('2 Phases'!$M$7,Calculation!$A$6:$A$126,0)),"")) -> 6.1134713 | R12: =IF('2 Phases'!$B$7<>"yes","",'2 Phases'!$K$7) -> OK
A13: Perfusion medium used | B13: =SUM(Calculation!$I$6:$I$126) -> 7.65744 | C13: L | E13: =IF('2 Phases'!$B$8<>"yes","",2) -> 2 | F13: =IF('2 Phases'!$B$8<>"yes","",'2 Phases'!$C$8) -> Fed-batch | G13: =IF('2 Phases'!$B$8<>"yes","",'2 Phases'!$L$8) -> 2 | H13: =IF('2 Phases'!$B$8<>"yes","",'2 Phases'!$M$8) -> 4 | I13: =IF('2 Phases'!$B$8<>"yes","",'2 Phases'!$N$8) -> 2370000 | J13: =IF('2 Phases'!$B$8<>"yes","",'2 Phases'!$O$8) -> 7000000 | K13: =IF('2 Phases'!$B$8<>"yes","",SUMIF(Calculation!$B$6:$B$126,2,Calculation!$F$6:$F$126)) -> 0.06 | L13: =IF('2 Phases'!$B$8<>"yes","",SUMIF(Calculation!$B$6:$B$126,2,Calculation!$I$6:$I$126)) -> 0 | M13: =IF('2 Phases'!$B$8<>"yes","",SUMIF(Calculation!$B$6:$B$126,2,Calculation!$J$6:$J$126)) -> 0 | N13: =IF('2 Phases'!$B$8<>"yes","",SUMIF(Calculation!$B$6:$B$126,2,Calculation!$K$6:$K$126)) -> 0 | O13: =IF('2 Phases'!$B$8<>"yes","",SUMIF(Calculation!$B$6:$B$126,2,Calculation!$L$6:$L$126)) -> 0 | P13: =IF('2 Phases'!$B$8<>"yes","",IFERROR(INDEX(Calculation!$Q$6:$Q$126,MATCH('2 Phases'!$M$8,Calculation!$A$6:$A$126,0)),"")) -> 9.6736837 | Q13: =IF('2 Phases'!$B$8<>"yes","",IFERROR(INDEX(Calculation!$R$6:$R$126,MATCH('2 Phases'!$M$8,Calculation!$A$6:$A$126,0)),"")) -> 23.818423 | R13: =IF('2 Phases'!$B$8<>"yes","",'2 Phases'!$K$8) -> OK
A14: TOTAL FRESH MEDIUM | B14: =INDEX(Calculation!$M$6:$M$126,MATCH('2 Phases'!$D$4,Calculation!$A$6:$A$126,0)) -> 8.71744 | C14: L | E14: =IF('2 Phases'!$B$9<>"yes","",3) -> 3 | F14: =IF('2 Phases'!$B$9<>"yes","",'2 Phases'!$C$9) -> Continuous | G14: =IF('2 Phases'!$B$9<>"yes","",'2 Phases'!$L$9) -> 4 | H14: =IF('2 Phases'!$B$9<>"yes","",'2 Phases'!$M$9) -> 14 | I14: =IF('2 Phases'!$B$9<>"yes","",'2 Phases'!$N$9) -> 7000000 | J14: =IF('2 Phases'!$B$9<>"yes","",'2 Phases'!$O$9) -> 7000000 | K14: =IF('2 Phases'!$B$9<>"yes","",SUMIF(Calculation!$B$6:$B$126,3,Calculation!$F$6:$F$126)) -> 0 | L14: =IF('2 Phases'!$B$9<>"yes","",SUMIF(Calculation!$B$6:$B$126,3,Calculation!$I$6:$I$126)) -> 7.65744 | M14: =IF('2 Phases'!$B$9<>"yes","",SUMIF(Calculation!$B$6:$B$126,3,Calculation!$J$6:$J$126)) -> 5.740007 | N14: =IF('2 Phases'!$B$9<>"yes","",SUMIF(Calculation!$B$6:$B$126,3,Calculation!$K$6:$K$126)) -> 1.917433 | O14: =IF('2 Phases'!$B$9<>"yes","",SUMIF(Calculation!$B$6:$B$126,3,Calculation!$L$6:$L$126)) -> 4.0180049e+10 | P14: =IF('2 Phases'!$B$9<>"yes","",IFERROR(INDEX(Calculation!$Q$6:$Q$126,MATCH('2 Phases'!$M$9,Calculation!$A$6:$A$126,0)),"")) -> 6.6350846 | Q14: =IF('2 Phases'!$B$9<>"yes","",IFERROR(INDEX(Calculation!$R$6:$R$126,MATCH('2 Phases'!$M$9,Calculation!$A$6:$A$126,0)),"")) -> 20.002292 | R14: =IF('2 Phases'!$B$9<>"yes","",'2 Phases'!$K$9) -> OK
A15: Bleed volume | B15: =INDEX(Calculation!$O$6:$O$126,MATCH('2 Phases'!$D$4,Calculation!$A$6:$A$126,0)) -> 5.740007 | C15: L | E15: =IF('2 Phases'!$B$10<>"yes","",4) | F15: =IF('2 Phases'!$B$10<>"yes","",'2 Phases'!$C$10) | G15: =IF('2 Phases'!$B$10<>"yes","",'2 Phases'!$L$10) | H15: =IF('2 Phases'!$B$10<>"yes","",'2 Phases'!$M$10) | I15: =IF('2 Phases'!$B$10<>"yes","",'2 Phases'!$N$10) | J15: =IF('2 Phases'!$B$10<>"yes","",'2 Phases'!$O$10) | K15: =IF('2 Phases'!$B$10<>"yes","",SUMIF(Calculation!$B$6:$B$126,4,Calculation!$F$6:$F$126)) | L15: =IF('2 Phases'!$B$10<>"yes","",SUMIF(Calculation!$B$6:$B$126,4,Calculation!$I$6:$I$126)) | M15: =IF('2 Phases'!$B$10<>"yes","",SUMIF(Calculation!$B$6:$B$126,4,Calculation!$J$6:$J$126)) | N15: =IF('2 Phases'!$B$10<>"yes","",SUMIF(Calculation!$B$6:$B$126,4,Calculation!$K$6:$K$126)) | O15: =IF('2 Phases'!$B$10<>"yes","",SUMIF(Calculation!$B$6:$B$126,4,Calculation!$L$6:$L$126)) | P15: =IF('2 Phases'!$B$10<>"yes","",IFERROR(INDEX(Calculation!$Q$6:$Q$126,MATCH('2 Phases'!$M$10,Calculation!$A$6:$A$126,0)),"")) | Q15: =IF('2 Phases'!$B$10<>"yes","",IFERROR(INDEX(Calculation!$R$6:$R$126,MATCH('2 Phases'!$M$10,Calculation!$A$6:$A$126,0)),"")) | R15: =IF('2 Phases'!$B$10<>"yes","",'2 Phases'!$K$10)
A16: Harvest volume (cell-free) | B16: =INDEX(Calculation!$N$6:$N$126,MATCH('2 Phases'!$D$4,Calculation!$A$6:$A$126,0)) -> 1.917433 | C16: L | E16: =IF('2 Phases'!$B$11<>"yes","",5) | F16: =IF('2 Phases'!$B$11<>"yes","",'2 Phases'!$C$11) | G16: =IF('2 Phases'!$B$11<>"yes","",'2 Phases'!$L$11) | H16: =IF('2 Phases'!$B$11<>"yes","",'2 Phases'!$M$11) | I16: =IF('2 Phases'!$B$11<>"yes","",'2 Phases'!$N$11) | J16: =IF('2 Phases'!$B$11<>"yes","",'2 Phases'!$O$11) | K16: =IF('2 Phases'!$B$11<>"yes","",SUMIF(Calculation!$B$6:$B$126,5,Calculation!$F$6:$F$126)) | L16: =IF('2 Phases'!$B$11<>"yes","",SUMIF(Calculation!$B$6:$B$126,5,Calculation!$I$6:$I$126)) | M16: =IF('2 Phases'!$B$11<>"yes","",SUMIF(Calculation!$B$6:$B$126,5,Calculation!$J$6:$J$126)) | N16: =IF('2 Phases'!$B$11<>"yes","",SUMIF(Calculation!$B$6:$B$126,5,Calculation!$K$6:$K$126)) | O16: =IF('2 Phases'!$B$11<>"yes","",SUMIF(Calculation!$B$6:$B$126,5,Calculation!$L$6:$L$126)) | P16: =IF('2 Phases'!$B$11<>"yes","",IFERROR(INDEX(Calculation!$Q$6:$Q$126,MATCH('2 Phases'!$M$11,Calculation!$A$6:$A$126,0)),"")) | Q16: =IF('2 Phases'!$B$11<>"yes","",IFERROR(INDEX(Calculation!$R$6:$R$126,MATCH('2 Phases'!$M$11,Calculation!$A$6:$A$126,0)),"")) | R16: =IF('2 Phases'!$B$11<>"yes","",'2 Phases'!$K$11)
A17: Cells inoculated | B17: ='1 Setup'!$B$6*'1 Setup'!$B$5*1000 -> 800000000 | C17: cells | E17: =IF('2 Phases'!$B$12<>"yes","",6) | F17: =IF('2 Phases'!$B$12<>"yes","",'2 Phases'!$C$12) | G17: =IF('2 Phases'!$B$12<>"yes","",'2 Phases'!$L$12) | H17: =IF('2 Phases'!$B$12<>"yes","",'2 Phases'!$M$12) | I17: =IF('2 Phases'!$B$12<>"yes","",'2 Phases'!$N$12) | J17: =IF('2 Phases'!$B$12<>"yes","",'2 Phases'!$O$12) | K17: =IF('2 Phases'!$B$12<>"yes","",SUMIF(Calculation!$B$6:$B$126,6,Calculation!$F$6:$F$126)) | L17: =IF('2 Phases'!$B$12<>"yes","",SUMIF(Calculation!$B$6:$B$126,6,Calculation!$I$6:$I$126)) | M17: =IF('2 Phases'!$B$12<>"yes","",SUMIF(Calculation!$B$6:$B$126,6,Calculation!$J$6:$J$126)) | N17: =IF('2 Phases'!$B$12<>"yes","",SUMIF(Calculation!$B$6:$B$126,6,Calculation!$K$6:$K$126)) | O17: =IF('2 Phases'!$B$12<>"yes","",SUMIF(Calculation!$B$6:$B$126,6,Calculation!$L$6:$L$126)) | P17: =IF('2 Phases'!$B$12<>"yes","",IFERROR(INDEX(Calculation!$Q$6:$Q$126,MATCH('2 Phases'!$M$12,Calculation!$A$6:$A$126,0)),"")) | Q17: =IF('2 Phases'!$B$12<>"yes","",IFERROR(INDEX(Calculation!$R$6:$R$126,MATCH('2 Phases'!$M$12,Calculation!$A$6:$A$126,0)),"")) | R17: =IF('2 Phases'!$B$12<>"yes","",'2 Phases'!$K$12)
A18: Cells in reactor at end | B18: =B6*B7*1000 -> 7420000000 | C18: cells
A19: Cells removed by bleed | B19: =INDEX(Calculation!$P$6:$P$126,MATCH('2 Phases'!$D$4,Calculation!$A$6:$A$126,0)) -> 4.0180049e+10 | C19: cells
A20: TOTAL CELLS PRODUCED | B20: =B18+B19-B17 -> 4.6800049e+10 | C20: cells
A21: Wet biomass in reactor at end | B21: =B18*'1 Setup'!$B$7/1000000000 -> 14.84 | C21: g
A22: Wet biomass removed by bleed | B22: =B19*'1 Setup'!$B$7/1000000000 -> 80.360098 | C22: g
A23: TOTAL WET BIOMASS PRODUCED | B23: =B20*'1 Setup'!$B$7/1000000000 -> 93.600098 | C23: g
A26: Charts (below) read the 'Chart data' tab. Compare several planners in 'Bioprocess visualization (modular)'.

Sheet Calculation
A1: Calculation – automatic, day by day (no input here)
A2: Rows after the end of the process stay empty. Fed-batch rows are orange, continuous rows blue.
P3: limit → | Q3: =IF('1 Setup'!$D$10="","",'1 Setup'!$D$10) -> 5 | R3: =IF('1 Setup'!$D$11="","",'1 Setup'!$D$11) -> 20 | S3: =IF('1 Setup'!$D$12="","",'1 Setup'!$D$12) -> 0.5 | T3: =IF('1 Setup'!$D$13="","",'1 Setup'!$D$13) -> 0.5 | U3: =IF('1 Setup'!$D$14="","",'1 Setup'!$D$14) -> 5
P4: sign → | Q4: ='1 Setup'!$H$10 -> -1 | R4: ='1 Setup'!$H$11 -> 1 | S4: ='1 Setup'!$H$12 -> -1 | T4: ='1 Setup'!$H$13 -> -1 | U4: ='1 Setup'!$H$14 -> 1
A5: Day | B5: Phase # | C5: Phase type | D5: Day in phase | E5: VCC (cells/mL) | F5: Fed-batch bolus (L) | G5: Working volume (L) | H5: Avg VCC over day (cells/mL) | I5: Perfusion feed (L) | J5: Bleed (L) | K5: Harvest (L) | L5: Cells removed by bleed | M5: Cum. fresh medium (L) | N5: Cum. harvest (L) | O5: Cum. bleed (L) | P5: Cum. cells bled | Q5: Glucose (mM) | R5: Lactate (mM) | S5: Glutamine (mM) | T5: Glutamate (mM) | U5: Ammonia (mM) | V5: Wet biomass (g/L) | W5: Wet biomass in reactor (g) | X5: Cum. wet biomass in bleed (g) | Y5: Wet biomass in bleed per day (g)
A6: 0 | B6: =IF(A6>'2 Phases'!$D$4,"",IF(A6=0,1,COUNTIF('2 Phases'!$M$7:$M$12,"<"&A6)+1)) -> 1 | C6: =IF($B6="","",INDEX('2 Phases'!$C$7:$C$12,B6)) -> Batch | D6: =IF($B6="","",A6-INDEX('2 Phases'!$L$7:$L$12,B6)) -> 0 | E6: ='1 Setup'!$B$6 -> 800000 | F6: 0 | G6: ='1 Setup'!$B$5 -> 1 | I6: 0 | J6: 0 | K6: 0 | L6: 0 | M6: =G6 -> 1 | N6: 0 | O6: 0 | P6: 0 | Q6: =IF('1 Setup'!$E$10="","",'1 Setup'!$E$10) -> 25 | R6: =IF('1 Setup'!$E$11="","",'1 Setup'!$E$11) -> 0 | S6: =IF('1 Setup'!$E$12="","",'1 Setup'!$E$12) | T6: =IF('1 Setup'!$E$13="","",'1 Setup'!$E$13) | U6: =IF('1 Setup'!$E$14="","",'1 Setup'!$E$14) | V6: =IF($B6="","",E6/1000000*'1 Setup'!$B$7) -> 1.6 | W6: =IF($B6="","",V6*G6) -> 1.6 | X6: =IF($B6="","",P6*'1 Setup'!$B$7/1000000000) -> 0 | Y6: =IF($B6="","",L6*'1 Setup'!$B$7/1000000000) -> 0
A7: 1 | B7: =IF(A7>'2 Phases'!$D$4,"",IF(A7=0,1,COUNTIF('2 Phases'!$M$7:$M$12,"<"&A7)+1)) -> 1 | C7: =IF($B7="","",INDEX('2 Phases'!$C$7:$C$12,B7)) -> Batch | D7: =IF($B7="","",A7-INDEX('2 Phases'!$L$7:$L$12,B7)) -> 1 | E7: =IF($B7="","",IFERROR(IF(C7="Continuous",INDEX('2 Phases'!$N$7:$N$12,B7)*EXP((INDEX('2 Phases'!$P$7:$P$12,B7)-N(INDEX('2 Phases'!$H$7:$H$12,B7)))*D7),INDEX('2 Phases'!$N$7:$N$12,B7)*(IF(INDEX('2 Phases'!$E$7:$E$12,B7)="",INDEX('2 Phases'!$N$7:$N$12,B7),INDEX('2 Phases'!$E$7:$E$12,B7))/INDEX('2 Phases'!$N$7:$N$12,B7))^(D7/INDEX('2 Phases'!$D$7:$D$12,B7))),"")) -> 1376953.2 | F7: =IF(OR($B7="",C7<>"Fed-batch",D7=0),0,IFERROR(N(INDEX('3 Feed regimes'!$B$6:$E$35,D7,MATCH(INDEX('2 Phases'!$F$7:$F$12,B7),'3 Feed regimes'!$B$4:$E$4,0)))*'1 Setup'!$B$5/100,0)) -> 0 | G7: =IF($B7="","",G6+F7) -> 1 | H7: =IF($B7="","",(E6+E7)/2) -> 1088476.6 | I7: =IF($B7="","",IF(C7="Continuous",N(INDEX('2 Phases'!$G$7:$G$12,B7))*G6,0)) -> 0 | J7: =IF($B7="","",IF(C7="Continuous",N(INDEX('2 Phases'!$H$7:$H$12,B7))*G6,0)) -> 0 | K7: =IF($B7="","",I7-J7) -> 0 | L7: =IF($B7="","",J7*1000*H7) -> 0 | M7: =IF($B7="","",M6+F7+I7) -> 1 | N7: =IF($B7="","",N6+K7) -> 0 | O7: =IF($B7="","",O6+J7) -> 0 | P7: =IF($B7="","",P6+L7) -> 0 | Q7: =IF(OR($B7="",Q6="",'1 Setup'!$C$10=""),"",IF(AND($C7="Continuous",N(INDEX('2 Phases'!$G$7:$G$12,B7))>0),IF('1 Setup'!$G$10="","",MAX(0,('1 Setup'!$G$10+('1 Setup'!$H$10*'1 Setup'!$C$10*0.00000024*$H7)/N(INDEX('2 Phases'!$G$7:$G$12,B7)))+(((Q6*($G6-$F6)+N('1 Setup'!$F$10)*$F6)/$G6)-('1 Setup'!$G$10+('1 Setup'!$H$10*'1 Setup'!$C$10*0.00000024*$H7)/N(INDEX('2 Phases'!$G$7:$G$12,B7))))*EXP(-N(INDEX('2 Phases'!$G$7:$G$12,B7))))),MAX(0,((Q6*($G6-$F6)+N('1 Setup'!$F$10)*$F6)/$G6)+('1 Setup'!$H$10*'1 Setup'!$C$10*0.00000024*$H7)))) -> 22.936248 | R7: =IF(OR($B7="",R6="",'1 Setup'!$C$11=""),"",IF(AND($C7="Continuous",N(INDEX('2 Phases'!$G$7:$G$12,B7))>0),IF('1 Setup'!$G$11="","",MAX(0,('1 Setup'!$G$11+('1 Setup'!$H$11*'1 Setup'!$C$11*0.00000024*$H7)/N(INDEX('2 Phases'!$G$7:$G$12,B7)))+(((R6*($G6-$F6)+N('1 Setup'!$F$11)*$F6)/$G6)-('1 Setup'!$G$11+('1 Setup'!$H$11*'1 Setup'!$C$11*0.00000024*$H7)/N(INDEX('2 Phases'!$G$7:$G$12,B7))))*EXP(-N(INDEX('2 Phases'!$G$7:$G$12,B7))))),MAX(0,((R6*($G6-$F6)+N('1 Setup'!$F$11)*$F6)/$G6)+('1 Setup'!$H$11*'1 Setup'!$C$11*0.00000024*$H7)))) -> 2.2466157 | S7: =IF(OR($B7="",S6="",'1 Setup'!$C$12=""),"",IF(AND($C7="Continuous",N(INDEX('2 Phases'!$G$7:$G$12,B7))>0),IF('1 Setup'!$G$12="","",MAX(0,('1 Setup'!$G$12+('1 Setup'!$H$12*'1 Setup'!$C$12*0.00000024*$H7)/N(INDEX('2 Phases'!$G$7:$G$12,B7)))+(((S6*($G6-$F6)+N('1 Setup'!$F$12)*$F6)/$G6)-('1 Setup'!$G$12+('1 Setup'!$H$12*'1 Setup'!$C$12*0.00000024*$H7)/N(INDEX('2 Phases'!$G$7:$G$12,B7))))*EXP(-N(INDEX('2 Phases'!$G$7:$G$12,B7))))),MAX(0,((S6*($G6-$F6)+N('1 Setup'!$F$12)*$F6)/$G6)+('1 Setup'!$H$12*'1 Setup'!$C$12*0.00000024*$H7)))) | T7: =IF(OR($B7="",T6="",'1 Setup'!$C$13=""),"",IF(AND($C7="Continuous",N(INDEX('2 Phases'!$G$7:$G$12,B7))>0),IF('1 Setup'!$G$13="","",MAX(0,('1 Setup'!$G$13+('1 Setup'!$H$13*'1 Setup'!$C$13*0.00000024*$H7)/N(INDEX('2 Phases'!$G$7:$G$12,B7)))+(((T6*($G6-$F6)+N('1 Setup'!$F$13)*$F6)/$G6)-('1 Setup'!$G$13+('1 Setup'!$H$13*'1 Setup'!$C$13*0.00000024*$H7)/N(INDEX('2 Phases'!$G$7:$G$12,B7))))*EXP(-N(INDEX('2 Phases'!$G$7:$G$12,B7))))),MAX(0,((T6*($G6-$F6)+N('1 Setup'!$F$13)*$F6)/$G6)+('1 Setup'!$H$13*'1 Setup'!$C$13*0.00000024*$H7)))) | U7: =IF(OR($B7="",U6="",'1 Setup'!$C$14=""),"",IF(AND($C7="Continuous",N(INDEX('2 Phases'!$G$7:$G$12,B7))>0),IF('1 Setup'!$G$14="","",MAX(0,('1 Setup'!$G$14+('1 Setup'!$H$14*'1 Setup'!$C$14*0.00000024*$H7)/N(INDEX('2 Phases'!$G$7:$G$12,B7)))+(((U6*($G6-$F6)+N('1 Setup'!$F$14)*$F6)/$G6)-('1 Setup'!$G$14+('1 Setup'!$H$14*'1 Setup'!$C$14*0.00000024*$H7)/N(INDEX('2 Phases'!$G$7:$G$12,B7))))*EXP(-N(INDEX('2 Phases'!$G$7:$G$12,B7))))),MAX(0,((U6*($G6-$F6)+N('1 Setup'!$F$14)*$F6)/$G6)+('1 Setup'!$H$14*'1 Setup'!$C$14*0.00000024*$H7)))) | V7: =IF($B7="","",E7/1000000*'1 Setup'!$B$7) -> 2.7539063 | W7: =IF($B7="","",V7*G7) -> 2.7539063 | X7: =IF($B7="","",P7*'1 Setup'!$B$7/1000000000) -> 0 | Y7: =IF($B7="","",L7*'1 Setup'!$B$7/1000000000) -> 0
A8: 2 | B8: =IF(A8>'2 Phases'!$D$4,"",IF(A8=0,1,COUNTIF('2 Phases'!$M$7:$M$12,"<"&A8)+1)) -> 1 | C8: =IF($B8="","",INDEX('2 Phases'!$C$7:$C$12,B8)) -> Batch | D8: =IF($B8="","",A8-INDEX('2 Phases'!$L$7:$L$12,B8)) -> 2 | E8: =IF($B8="","",IFERROR(IF(C8="Continuous",INDEX('2 Phases'!$N$7:$N$12,B8)*EXP((INDEX('2 Phases'!$P$7:$P$12,B8)-N(INDEX('2 Phases'!$H$7:$H$12,B8)))*D8),INDEX('2 Phases'!$N$7:$N$12,B8)*(IF(INDEX('2 Phases'!$E$7:$E$12,B8)="",INDEX('2 Phases'!$N$7:$N$12,B8),INDEX('2 Phases'!$E$7:$E$12,B8))/INDEX('2 Phases'!$N$7:$N$12,B8))^(D8/INDEX('2 Phases'!$D$7:$D$12,B8))),"")) -> 2370000 | F8: =IF(OR($B8="",C8<>"Fed-batch",D8=0),0,IFERROR(N(INDEX('3 Feed regimes'!$B$6:$E$35,D8,MATCH(INDEX('2 Phases'!$F$7:$F$12,B8),'3 Feed regimes'!$B$4:$E$4,0)))*'1 Setup'!$B$5/100,0)) -> 0 | G8: =IF($B8="","",G7+F8) -> 1 | H8: =IF($B8="","",(E7+E8)/2) -> 1873476.6 | I8: =IF($B8="","",IF(C8="Continuous",N(INDEX('2 Phases'!$G$7:$G$12,B8))*G7,0)) -> 0 | J8: =IF($B8="","",IF(C8="Continuous",N(INDEX('2 Phases'!$H$7:$H$12,B8))*G7,0)) -> 0 | K8: =IF($B8="","",I8-J8) -> 0 | L8: =IF($B8="","",J8*1000*H8) -> 0 | M8: =IF($B8="","",M7+F8+I8) -> 1 | N8: =IF($B8="","",N7+K8) -> 0 | O8: =IF($B8="","",O7+J8) -> 0 | P8: =IF($B8="","",P7+L8) -> 0 | Q8: =IF(OR($B8="",Q7="",'1 Setup'!$C$10=""),"",IF(AND($C8="Continuous",N(INDEX('2 Phases'!$G$7:$G$12,B8))>0),IF('1 Setup'!$G$10="","",MAX(0,('1 Setup'!$G$10+('1 Setup'!$H$10*'1 Setup'!$C$10*0.00000024*$H8)/N(INDEX('2 Phases'!$G$7:$G$12,B8)))+(((Q7*($G7-$F7)+N('1 Setup'!$F$10)*$F7)/$G7)-('1 Setup'!$G$10+('1 Setup'!$H$10*'1 Setup'!$C$10*0.00000024*$H8)/N(INDEX('2 Phases'!$G$7:$G$12,B8))))*EXP(-N(INDEX('2 Phases'!$G$7:$G$12,B8))))),MAX(0,((Q7*($G7-$F7)+N('1 Setup'!$F$10)*$F7)/$G7)+('1 Setup'!$H$10*'1 Setup'!$C$10*0.00000024*$H8)))) -> 19.384137 | R8: =IF(OR($B8="",R7="",'1 Setup'!$C$11=""),"",IF(AND($C8="Continuous",N(INDEX('2 Phases'!$G$7:$G$12,B8))>0),IF('1 Setup'!$G$11="","",MAX(0,('1 Setup'!$G$11+('1 Setup'!$H$11*'1 Setup'!$C$11*0.00000024*$H8)/N(INDEX('2 Phases'!$G$7:$G$12,B8)))+(((R7*($G7-$F7)+N('1 Setup'!$F$11)*$F7)/$G7)-('1 Setup'!$G$11+('1 Setup'!$H$11*'1 Setup'!$C$11*0.00000024*$H8)/N(INDEX('2 Phases'!$G$7:$G$12,B8))))*EXP(-N(INDEX('2 Phases'!$G$7:$G$12,B8))))),MAX(0,((R7*($G7-$F7)+N('1 Setup'!$F$11)*$F7)/$G7)+('1 Setup'!$H$11*'1 Setup'!$C$11*0.00000024*$H8)))) -> 6.1134713 | S8: =IF(OR($B8="",S7="",'1 Setup'!$C$12=""),"",IF(AND($C8="Continuous",N(INDEX('2 Phases'!$G$7:$G$12,B8))>0),IF('1 Setup'!$G$12="","",MAX(0,('1 Setup'!$G$12+('1 Setup'!$H$12*'1 Setup'!$C$12*0.00000024*$H8)/N(INDEX('2 Phases'!$G$7:$G$12,B8)))+(((S7*($G7-$F7)+N('1 Setup'!$F$12)*$F7)/$G7)-('1 Setup'!$G$12+('1 Setup'!$H$12*'1 Setup'!$C$12*0.00000024*$H8)/N(INDEX('2 Phases'!$G$7:$G$12,B8))))*EXP(-N(INDEX('2 Phases'!$G$7:$G$12,B8))))),MAX(0,((S7*($G7-$F7)+N('1 Setup'!$F$12)*$F7)/$G7)+('1 Setup'!$H$12*'1 Setup'!$C$12*0.00000024*$H8)))) | T8: =IF(OR($B8="",T7="",'1 Setup'!$C$13=""),"",IF(AND($C8="Continuous",N(INDEX('2 Phases'!$G$7:$G$12,B8))>0),IF('1 Setup'!$G$13="","",MAX(0,('1 Setup'!$G$13+('1 Setup'!$H$13*'1 Setup'!$C$13*0.00000024*$H8)/N(INDEX('2 Phases'!$G$7:$G$12,B8)))+(((T7*($G7-$F7)+N('1 Setup'!$F$13)*$F7)/$G7)-('1 Setup'!$G$13+('1 Setup'!$H$13*'1 Setup'!$C$13*0.00000024*$H8)/N(INDEX('2 Phases'!$G$7:$G$12,B8))))*EXP(-N(INDEX('2 Phases'!$G$7:$G$12,B8))))),MAX(0,((T7*($G7-$F7)+N('1 Setup'!$F$13)*$F7)/$G7)+('1 Setup'!$H$13*'1 Setup'!$C$13*0.00000024*$H8)))) | U8: =IF(OR($B8="",U7="",'1 Setup'!$C$14=""),"",IF(AND($C8="Continuous",N(INDEX('2 Phases'!$G$7:$G$12,B8))>0),IF('1 Setup'!$G$14="","",MAX(0,('1 Setup'!$G$14+('1 Setup'!$H$14*'1 Setup'!$C$14*0.00000024*$H8)/N(INDEX('2 Phases'!$G$7:$G$12,B8)))+(((U7*($G7-$F7)+N('1 Setup'!$F$14)*$F7)/$G7)-('1 Setup'!$G$14+('1 Setup'!$H$14*'1 Setup'!$C$14*0.00000024*$H8)/N(INDEX('2 Phases'!$G$7:$G$12,B8))))*EXP(-N(INDEX('2 Phases'!$G$7:$G$12,B8))))),MAX(0,((U7*($G7-$F7)+N('1 Setup'!$F$14)*$F7)/$G7)+('1 Setup'!$H$14*'1 Setup'!$C$14*0.00000024*$H8)))) | V8: =IF($B8="","",E8/1000000*'1 Setup'!$B$7) -> 4.74 | W8: =IF($B8="","",V8*G8) -> 4.74 | X8: =IF($B8="","",P8*'1 Setup'!$B$7/1000000000) -> 0 | Y8: =IF($B8="","",L8*'1 Setup'!$B$7/1000000000) -> 0
A9: 3 | B9: =IF(A9>'2 Phases'!$D$4,"",IF(A9=0,1,COUNTIF('2 Phases'!$M$7:$M$12,"<"&A9)+1)) -> 2 | C9: =IF($B9="","",INDEX('2 Phases'!$C$7:$C$12,B9)) -> Fed-batch | D9: =IF($B9="","",A9-INDEX('2 Phases'!$L$7:$L$12,B9)) -> 1 | E9: =IF($B9="","",IFERROR(IF(C9="Continuous",INDEX('2 Phases'!$N$7:$N$12,B9)*EXP((INDEX('2 Phases'!$P$7:$P$12,B9)-N(INDEX('2 Phases'!$H$7:$H$12,B9)))*D9),INDEX('2 Phases'!$N$7:$N$12,B9)*(IF(INDEX('2 Phases'!$E$7:$E$12,B9)="",INDEX('2 Phases'!$N$7:$N$12,B9),INDEX('2 Phases'!$E$7:$E$12,B9))/INDEX('2 Phases'!$N$7:$N$12,B9))^(D9/INDEX('2 Phases'!$D$7:$D$12,B9))),"")) -> 4073082.4 | F9: =IF(OR($B9="",C9<>"Fed-batch",D9=0),0,IFERROR(N(INDEX('3 Feed regimes'!$B$6:$E$35,D9,MATCH(INDEX('2 Phases'!$F$7:$F$12,B9),'3 Feed regimes'!$B$4:$E$4,0)))*'1 Setup'!$B$5/100,0)) -> 0.03 | G9: =IF($B9="","",G8+F9) -> 1.03 | H9: =IF($B9="","",(E8+E9)/2) -> 3221541.2 | I9: =IF($B9="","",IF(C9="Continuous",N(INDEX('2 Phases'!$G$7:$G$12,B9))*G8,0)) -> 0 | J9: =IF($B9="","",IF(C9="Continuous",N(INDEX('2 Phases'!$H$7:$H$12,B9))*G8,0)) -> 0 | K9: =IF($B9="","",I9-J9) -> 0 | L9: =IF($B9="","",J9*1000*H9) -> 0 | M9: =IF($B9="","",M8+F9+I9) -> 1.03 | N9: =IF($B9="","",N8+K9) -> 0 | O9: =IF($B9="","",O8+J9) -> 0 | P9: =IF($B9="","",P8+L9) -> 0 | Q9: =IF(OR($B9="",Q8="",'1 Setup'!$C$10=""),"",IF(AND($C9="Continuous",N(INDEX('2 Phases'!$G$7:$G$12,B9))>0),IF('1 Setup'!$G$10="","",MAX(0,('1 Setup'!$G$10+('1 Setup'!$H$10*'1 Setup'!$C$10*0.00000024*$H9)/N(INDEX('2 Phases'!$G$7:$G$12,B9)))+(((Q8*($G8-$F8)+N('1 Setup'!$F$10)*$F8)/$G8)-('1 Setup'!$G$10+('1 Setup'!$H$10*'1 Setup'!$C$10*0.00000024*$H9)/N(INDEX('2 Phases'!$G$7:$G$12,B9))))*EXP(-N(INDEX('2 Phases'!$G$7:$G$12,B9))))),MAX(0,((Q8*($G8-$F8)+N('1 Setup'!$F$10)*$F8)/$G8)+('1 Setup'!$H$10*'1 Setup'!$C$10*0.00000024*$H9)))) -> 13.276095 | R9: =IF(OR($B9="",R8="",'1 Setup'!$C$11=""),"",IF(AND($C9="Continuous",N(INDEX('2 Phases'!$G$7:$G$12,B9))>0),IF('1 Setup'!$G$11="","",MAX(0,('1 Setup'!$G$11+('1 Setup'!$H$11*'1 Setup'!$C$11*0.00000024*$H9)/N(INDEX('2 Phases'!$G$7:$G$12,B9)))+(((R8*($G8-$F8)+N('1 Setup'!$F$11)*$F8)/$G8)-('1 Setup'!$G$11+('1 Setup'!$H$11*'1 Setup'!$C$11*0.00000024*$H9)/N(INDEX('2 Phases'!$G$7:$G$12,B9))))*EXP(-N(INDEX('2 Phases'!$G$7:$G$12,B9))))),MAX(0,((R8*($G8-$F8)+N('1 Setup'!$F$11)*$F8)/$G8)+('1 Setup'!$H$11*'1 Setup'!$C$11*0.00000024*$H9)))) -> 12.762732 | S9: =IF(OR($B9="",S8="",'1 Setup'!$C$12=""),"",IF(AND($C9="Continuous",N(INDEX('2 Phases'!$G$7:$G$12,B9))>0),IF('1 Setup'!$G$12="","",MAX(0,('1 Setup'!$G$12+('1 Setup'!$H$12*'1 Setup'!$C$12*0.00000024*$H9)/N(INDEX('2 Phases'!$G$7:$G$12,B9)))+(((S8*($G8-$F8)+N('1 Setup'!$F$12)*$F8)/$G8)-('1 Setup'!$G$12+('1 Setup'!$H$12*'1 Setup'!$C$12*0.00000024*$H9)/N(INDEX('2 Phases'!$G$7:$G$12,B9))))*EXP(-N(INDEX('2 Phases'!$G$7:$G$12,B9))))),MAX(0,((S8*($G8-$F8)+N('1 Setup'!$F$12)*$F8)/$G8)+('1 Setup'!$H$12*'1 Setup'!$C$12*0.00000024*$H9)))) | T9: =IF(OR($B9="",T8="",'1 Setup'!$C$13=""),"",IF(AND($C9="Continuous",N(INDEX('2 Phases'!$G$7:$G$12,B9))>0),IF('1 Setup'!$G$13="","",MAX(0,('1 Setup'!$G$13+('1 Setup'!$H$13*'1 Setup'!$C$13*0.00000024*$H9)/N(INDEX('2 Phases'!$G$7:$G$12,B9)))+(((T8*($G8-$F8)+N('1 Setup'!$F$13)*$F8)/$G8)-('1 Setup'!$G$13+('1 Setup'!$H$13*'1 Setup'!$C$13*0.00000024*$H9)/N(INDEX('2 Phases'!$G$7:$G$12,B9))))*EXP(-N(INDEX('2 Phases'!$G$7:$G$12,B9))))),MAX(0,((T8*($G8-$F8)+N('1 Setup'!$F$13)*$F8)/$G8)+('1 Setup'!$H$13*'1 Setup'!$C$13*0.00000024*$H9)))) | U9: =IF(OR($B9="",U8="",'1 Setup'!$C$14=""),"",IF(AND($C9="Continuous",N(INDEX('2 Phases'!$G$7:$G$12,B9))>0),IF('1 Setup'!$G$14="","",MAX(0,('1 Setup'!$G$14+('1 Setup'!$H$14*'1 Setup'!$C$14*0.00000024*$H9)/N(INDEX('2 Phases'!$G$7:$G$12,B9)))+(((U8*($G8-$F8)+N('1 Setup'!$F$14)*$F8)/$G8)-('1 Setup'!$G$14+('1 Setup'!$H$14*'1 Setup'!$C$14*0.00000024*$H9)/N(INDEX('2 Phases'!$G$7:$G$12,B9))))*EXP(-N(INDEX('2 Phases'!$G$7:$G$12,B9))))),MAX(0,((U8*($G8-$F8)+N('1 Setup'!$F$14)*$F8)/$G8)+('1 Setup'!$H$14*'1 Setup'!$C$14*0.00000024*$H9)))) | V9: =IF($B9="","",E9/1000000*'1 Setup'!$B$7) -> 8.1461647 | W9: =IF($B9="","",V9*G9) -> 8.3905497 | X9: =IF($B9="","",P9*'1 Setup'!$B$7/1000000000) -> 0 | Y9: =IF($B9="","",L9*'1 Setup'!$B$7/1000000000) -> 0
A10: 4 | B10: =IF(A10>'2 Phases'!$D$4,"",IF(A10=0,1,COUNTIF('2 Phases'!$M$7:$M$12,"<"&A10)+1)) -> 2 | C10: =IF($B10="","",INDEX('2 Phases'!$C$7:$C$12,B10)) -> Fed-batch | D10: =IF($B10="","",A10-INDEX('2 Phases'!$L$7:$L$12,B10)) -> 2 | E10: =IF($B10="","",IFERROR(IF(C10="Continuous",INDEX('2 Phases'!$N$7:$N$12,B10)*EXP((INDEX('2 Phases'!$P$7:$P$12,B10)-N(INDEX('2 Phases'!$H$7:$H$12,B10)))*D10),INDEX('2 Phases'!$N$7:$N$12,B10)*(IF(INDEX('2 Phases'!$E$7:$E$12,B10)="",INDEX('2 Phases'!$N$7:$N$12,B10),INDEX('2 Phases'!$E$7:$E$12,B10))/INDEX('2 Phases'!$N$7:$N$12,B10))^(D10/INDEX('2 Phases'!$D$7:$D$12,B10))),"")) -> 7000000 | F10: =IF(OR($B10="",C10<>"Fed-batch",D10=0),0,IFERROR(N(INDEX('3 Feed regimes'!$B$6:$E$35,D10,MATCH(INDEX('2 Phases'!$F$7:$F$12,B10),'3 Feed regimes'!$B$4:$E$4,0)))*'1 Setup'!$B$5/100,0)) -> 0.03 | G10: =IF($B10="","",G9+F10) -> 1.06 | H10: =IF($B10="","",(E9+E10)/2) -> 5536541.2 | I10: =IF($B10="","",IF(C10="Continuous",N(INDEX('2 Phases'!$G$7:$G$12,B10))*G9,0)) -> 0 | J10: =IF($B10="","",IF(C10="Continuous",N(INDEX('2 Phases'!$H$7:$H$12,B10))*G9,0)) -> 0 | K10: =IF($B10="","",I10-J10) -> 0 | L10: =IF($B10="","",J10*1000*H10) -> 0 | M10: =IF($B10="","",M9+F10+I10) -> 1.06 | N10: =IF($B10="","",N9+K10) -> 0 | O10: =IF($B10="","",O9+J10) -> 0 | P10: =IF($B10="","",P9+L10) -> 0 | Q10: =IF(OR($B10="",Q9="",'1 Setup'!$C$10=""),"",IF(AND($C10="Continuous",N(INDEX('2 Phases'!$G$7:$G$12,B10))>0),IF('1 Setup'!$G$10="","",MAX(0,('1 Setup'!$G$10+('1 Setup'!$H$10*'1 Setup'!$C$10*0.00000024*$H10)/N(INDEX('2 Phases'!$G$7:$G$12,B10)))+(((Q9*($G9-$F9)+N('1 Setup'!$F$10)*$F9)/$G9)-('1 Setup'!$G$10+('1 Setup'!$H$10*'1 Setup'!$C$10*0.00000024*$H10)/N(INDEX('2 Phases'!$G$7:$G$12,B10))))*EXP(-N(INDEX('2 Phases'!$G$7:$G$12,B10))))),MAX(0,((Q9*($G9-$F9)+N('1 Setup'!$F$10)*$F9)/$G9)+('1 Setup'!$H$10*'1 Setup'!$C$10*0.00000024*$H10)))) -> 9.6736837 | R10: =IF(OR($B10="",R9="",'1 Setup'!$C$11=""),"",IF(AND($C10="Continuous",N(INDEX('2 Phases'!$G$7:$G$12,B10))>0),IF('1 Setup'!$G$11="","",MAX(0,('1 Setup'!$G$11+('1 Setup'!$H$11*'1 Setup'!$C$11*0.00000024*$H10)/N(INDEX('2 Phases'!$G$7:$G$12,B10)))+(((R9*($G9-$F9)+N('1 Setup'!$F$11)*$F9)/$G9)-('1 Setup'!$G$11+('1 Setup'!$H$11*'1 Setup'!$C$11*0.00000024*$H10)/N(INDEX('2 Phases'!$G$7:$G$12,B10))))*EXP(-N(INDEX('2 Phases'!$G$7:$G$12,B10))))),MAX(0,((R9*($G9-$F9)+N('1 Setup'!$F$11)*$F9)/$G9)+('1 Setup'!$H$11*'1 Setup'!$C$11*0.00000024*$H10)))) -> 23.818423 | S10: =IF(OR($B10="",S9="",'1 Setup'!$C$12=""),"",IF(AND($C10="Continuous",N(INDEX('2 Phases'!$G$7:$G$12,B10))>0),IF('1 Setup'!$G$12="","",MAX(0,('1 Setup'!$G$12+('1 Setup'!$H$12*'1 Setup'!$C$12*0.00000024*$H10)/N(INDEX('2 Phases'!$G$7:$G$12,B10)))+(((S9*($G9-$F9)+N('1 Setup'!$F$12)*$F9)/$G9)-('1 Setup'!$G$12+('1 Setup'!$H$12*'1 Setup'!$C$12*0.00000024*$H10)/N(INDEX('2 Phases'!$G$7:$G$12,B10))))*EXP(-N(INDEX('2 Phases'!$G$7:$G$12,B10))))),MAX(0,((S9*($G9-$F9)+N('1 Setup'!$F$12)*$F9)/$G9)+('1 Setup'!$H$12*'1 Setup'!$C$12*0.00000024*$H10)))) | T10: =IF(OR($B10="",T9="",'1 Setup'!$C$13=""),"",IF(AND($C10="Continuous",N(INDEX('2 Phases'!$G$7:$G$12,B10))>0),IF('1 Setup'!$G$13="","",MAX(0,('1 Setup'!$G$13+('1 Setup'!$H$13*'1 Setup'!$C$13*0.00000024*$H10)/N(INDEX('2 Phases'!$G$7:$G$12,B10)))+(((T9*($G9-$F9)+N('1 Setup'!$F$13)*$F9)/$G9)-('1 Setup'!$G$13+('1 Setup'!$H$13*'1 Setup'!$C$13*0.00000024*$H10)/N(INDEX('2 Phases'!$G$7:$G$12,B10))))*EXP(-N(INDEX('2 Phases'!$G$7:$G$12,B10))))),MAX(0,((T9*($G9-$F9)+N('1 Setup'!$F$13)*$F9)/$G9)+('1 Setup'!$H$13*'1 Setup'!$C$13*0.00000024*$H10)))) | U10: =IF(OR($B10="",U9="",'1 Setup'!$C$14=""),"",IF(AND($C10="Continuous",N(INDEX('2 Phases'!$G$7:$G$12,B10))>0),IF('1 Setup'!$G$14="","",MAX(0,('1 Setup'!$G$14+('1 Setup'!$H$14*'1 Setup'!$C$14*0.00000024*$H10)/N(INDEX('2 Phases'!$G$7:$G$12,B10)))+(((U9*($G9-$F9)+N('1 Setup'!$F$14)*$F9)/$G9)-('1 Setup'!$G$14+('1 Setup'!$H$14*'1 Setup'!$C$14*0.00000024*$H10)/N(INDEX('2 Phases'!$G$7:$G$12,B10))))*EXP(-N(INDEX('2 Phases'!$G$7:$G$12,B10))))),MAX(0,((U9*($G9-$F9)+N('1 Setup'!$F$14)*$F9)/$G9)+('1 Setup'!$H$14*'1 Setup'!$C$14*0.00000024*$H10)))) | V10: =IF($B10="","",E10/1000000*'1 Setup'!$B$7) -> 14 | W10: =IF($B10="","",V10*G10) -> 14.84 | X10: =IF($B10="","",P10*'1 Setup'!$B$7/1000000000) -> 0 | Y10: =IF($B10="","",L10*'1 Setup'!$B$7/1000000000) -> 0
A11: 5 | B11: =IF(A11>'2 Phases'!$D$4,"",IF(A11=0,1,COUNTIF('2 Phases'!$M$7:$M$12,"<"&A11)+1)) -> 3 | C11: =IF($B11="","",INDEX('2 Phases'!$C$7:$C$12,B11)) -> Continuous | D11: =IF($B11="","",A11-INDEX('2 Phases'!$L$7:$L$12,B11)) -> 1 | E11: =IF($B11="","",IFERROR(IF(C11="Continuous",INDEX('2 Phases'!$N$7:$N$12,B11)*EXP((INDEX('2 Phases'!$P$7:$P$12,B11)-N(INDEX('2 Phases'!$H$7:$H$12,B11)))*D11),INDEX('2 Phases'!$N$7:$N$12,B11)*(IF(INDEX('2 Phases'!$E$7:$E$12,B11)="",INDEX('2 Phases'!$N$7:$N$12,B11),INDEX('2 Phases'!$E$7:$E$12,B11))/INDEX('2 Phases'!$N$7:$N$12,B11))^(D11/INDEX('2 Phases'!$D$7:$D$12,B11))),"")) -> 7000000 | F11: =IF(OR($B11="",C11<>"Fed-batch",D11=0),0,IFERROR(N(INDEX('3 Feed regimes'!$B$6:$E$35,D11,MATCH(INDEX('2 Phases'!$F$7:$F$12,B11),'3 Feed regimes'!$B$4:$E$4,0)))*'1 Setup'!$B$5/100,0)) -> 0 | G11: =IF($B11="","",G10+F11) -> 1.06 | H11: =IF($B11="","",(E10+E11)/2) -> 7000000 | I11: =IF($B11="","",IF(C11="Continuous",N(INDEX('2 Phases'!$G$7:$G$12,B11))*G10,0)) -> 0.765744 | J11: =IF($B11="","",IF(C11="Continuous",N(INDEX('2 Phases'!$H$7:$H$12,B11))*G10,0)) -> 0.5740007 | K11: =IF($B11="","",I11-J11) -> 0.1917433 | L11: =IF($B11="","",J11*1000*H11) -> 4.0180049e+09 | M11: =IF($B11="","",M10+F11+I11) -> 1.825744 | N11: =IF($B11="","",N10+K11) -> 0.1917433 | O11: =IF($B11="","",O10+J11) -> 0.5740007 | P11: =IF($B11="","",P10+L11) -> 4.0180049e+09 | Q11: =IF(OR($B11="",Q10="",'1 Setup'!$C$10=""),"",IF(AND($C11="Continuous",N(INDEX('2 Phases'!$G$7:$G$12,B11))>0),IF('1 Setup'!$G$10="","",MAX(0,('1 Setup'!$G$10+('1 Setup'!$H$10*'1 Setup'!$C$10*0.00000024*$H11)/N(INDEX('2 Phases'!$G$7:$G$12,B11)))+(((Q10*($G10-$F10)+N('1 Setup'!$F$10)*$F10)/$G10)-('1 Setup'!$G$10+('1 Setup'!$H$10*'1 Setup'!$C$10*0.00000024*$H11)/N(INDEX('2 Phases'!$G$7:$G$12,B11))))*EXP(-N(INDEX('2 Phases'!$G$7:$G$12,B11))))),MAX(0,((Q10*($G10-$F10)+N('1 Setup'!$F$10)*$F10)/$G10)+('1 Setup'!$H$10*'1 Setup'!$C$10*0.00000024*$H11)))) -> 11.409693 | R11: =IF(OR($B11="",R10="",'1 Setup'!$C$11=""),"",IF(AND($C11="Continuous",N(INDEX('2 Phases'!$G$7:$G$12,B11))>0),IF('1 Setup'!$G$11="","",MAX(0,('1 Setup'!$G$11+('1 Setup'!$H$11*'1 Setup'!$C$11*0.00000024*$H11)/N(INDEX('2 Phases'!$G$7:$G$12,B11)))+(((R10*($G10-$F10)+N('1 Setup'!$F$11)*$F10)/$G10)-('1 Setup'!$G$11+('1 Setup'!$H$11*'1 Setup'!$C$11*0.00000024*$H11)/N(INDEX('2 Phases'!$G$7:$G$12,B11))))*EXP(-N(INDEX('2 Phases'!$G$7:$G$12,B11))))),MAX(0,((R10*($G10-$F10)+N('1 Setup'!$F$11)*$F10)/$G10)+('1 Setup'!$H$11*'1 Setup'!$C$11*0.00000024*$H11)))) -> 21.526835 | S11: =IF(OR($B11="",S10="",'1 Setup'!$C$12=""),"",IF(AND($C11="Continuous",N(INDEX('2 Phases'!$G$7:$G$12,B11))>0),IF('1 Setup'!$G$12="","",MAX(0,('1 Setup'!$G$12+('1 Setup'!$H$12*'1 Setup'!$C$12*0.00000024*$H11)/N(INDEX('2 Phases'!$G$7:$G$12,B11)))+(((S10*($G10-$F10)+N('1 Setup'!$F$12)*$F10)/$G10)-('1 Setup'!$G$12+('1 Setup'!$H$12*'1 Setup'!$C$12*0.00000024*$H11)/N(INDEX('2 Phases'!$G$7:$G$12,B11))))*EXP(-N(INDEX('2 Phases'!$G$7:$G$12,B11))))),MAX(0,((S10*($G10-$F10)+N('1 Setup'!$F$12)*$F10)/$G10)+('1 Setup'!$H$12*'1 Setup'!$C$12*0.00000024*$H11)))) | T11: =IF(OR($B11="",T10="",'1 Setup'!$C$13=""),"",IF(AND($C11="Continuous",N(INDEX('2 Phases'!$G$7:$G$12,B11))>0),IF('1 Setup'!$G$13="","",MAX(0,('1 Setup'!$G$13+('1 Setup'!$H$13*'1 Setup'!$C$13*0.00000024*$H11)/N(INDEX('2 Phases'!$G$7:$G$12,B11)))+(((T10*($G10-$F10)+N('1 Setup'!$F$13)*$F10)/$G10)-('1 Setup'!$G$13+('1 Setup'!$H$13*'1 Setup'!$C$13*0.00000024*$H11)/N(INDEX('2 Phases'!$G$7:$G$12,B11))))*EXP(-N(INDEX('2 Phases'!$G$7:$G$12,B11))))),MAX(0,((T10*($G10-$F10)+N('1 Setup'!$F$13)*$F10)/$G10)+('1 Setup'!$H$13*'1 Setup'!$C$13*0.00000024*$H11)))) | U11: =IF(OR($B11="",U10="",'1 Setup'!$C$14=""),"",IF(AND($C11="Continuous",N(INDEX('2 Phases'!$G$7:$G$12,B11))>0),IF('1 Setup'!$G$14="","",MAX(0,('1 Setup'!$G$14+('1 Setup'!$H$14*'1 Setup'!$C$14*0.00000024*$H11)/N(INDEX('2 Phases'!$G$7:$G$12,B11)))+(((U10*($G10-$F10)+N('1 Setup'!$F$14)*$F10)/$G10)-('1 Setup'!$G$14+('1 Setup'!$H$14*'1 Setup'!$C$14*0.00000024*$H11)/N(INDEX('2 Phases'!$G$7:$G$12,B11))))*EXP(-N(INDEX('2 Phases'!$G$7:$G$12,B11))))),MAX(0,((U10*($G10-$F10)+N('1 Setup'!$F$14)*$F10)/$G10)+('1 Setup'!$H$14*'1 Setup'!$C$14*0.00000024*$H11)))) | V11: =IF($B11="","",E11/1000000*'1 Setup'!$B$7) -> 14 | W11: =IF($B11="","",V11*G11) -> 14.84 | X11: =IF($B11="","",P11*'1 Setup'!$B$7/1000000000) -> 8.0360098 | Y11: =IF($B11="","",L11*'1 Setup'!$B$7/1000000000) -> 8.0360098
A12: 6 | B12: =IF(A12>'2 Phases'!$D$4,"",IF(A12=0,1,COUNTIF('2 Phases'!$M$7:$M$12,"<"&A12)+1)) -> 3 | C12: =IF($B12="","",INDEX('2 Phases'!$C$7:$C$12,B12)) -> Continuous | D12: =IF($B12="","",A12-INDEX('2 Phases'!$L$7:$L$12,B12)) -> 2 | E12: =IF($B12="","",IFERROR(IF(C12="Continuous",INDEX('2 Phases'!$N$7:$N$12,B12)*EXP((INDEX('2 Phases'!$P$7:$P$12,B12)-N(INDEX('2 Phases'!$H$7:$H$12,B12)))*D12),INDEX('2 Phases'!$N$7:$N$12,B12)*(IF(INDEX('2 Phases'!$E$7:$E$12,B12)="",INDEX('2 Phases'!$N$7:$N$12,B12),INDEX('2 Phases'!$E$7:$E$12,B12))/INDEX('2 Phases'!$N$7:$N$12,B12))^(D12/INDEX('2 Phases'!$D$7:$D$12,B12))),"")) -> 7000000 | F12: =IF(OR($B12="",C12<>"Fed-batch",D12=0),0,IFERROR(N(INDEX('3 Feed regimes'!$B$6:$E$35,D12,MATCH(INDEX('2 Phases'!$F$7:$F$12,B12),'3 Feed regimes'!$B$4:$E$4,0)))*'1 Setup'!$B$5/100,0)) -> 0 | G12: =IF($B12="","",G11+F12) -> 1.06 | H12: =IF($B12="","",(E11+E12)/2) -> 7000000 | I12: =IF($B12="","",IF(C12="Continuous",N(INDEX('2 Phases'!$G$7:$G$12,B12))*G11,0)) -> 0.765744 | J12: =IF($B12="","",IF(C12="Continuous",N(INDEX('2 Phases'!$H$7:$H$12,B12))*G11,0)) -> 0.5740007 | K12: =IF($B12="","",I12-J12) -> 0.1917433 | L12: =IF($B12="","",J12*1000*H12) -> 4.0180049e+09 | M12: =IF($B12="","",M11+F12+I12) -> 2.591488 | N12: =IF($B12="","",N11+K12) -> 0.38348659 | O12: =IF($B12="","",O11+J12) -> 1.1480014 | P12: =IF($B12="","",P11+L12) -> 8.0360098e+09 | Q12: =IF(OR($B12="",Q11="",'1 Setup'!$C$10=""),"",IF(AND($C12="Continuous",N(INDEX('2 Phases'!$G$7:$G$12,B12))>0),IF('1 Setup'!$G$10="","",MAX(0,('1 Setup'!$G$10+('1 Setup'!$H$10*'1 Setup'!$C$10*0.00000024*$H12)/N(INDEX('2 Phases'!$G$7:$G$12,B12)))+(((Q11*($G11-$F11)+N('1 Setup'!$F$10)*$F11)/$G11)-('1 Setup'!$G$10+('1 Setup'!$H$10*'1 Setup'!$C$10*0.00000024*$H12)/N(INDEX('2 Phases'!$G$7:$G$12,B12))))*EXP(-N(INDEX('2 Phases'!$G$7:$G$12,B12))))),MAX(0,((Q11*($G11-$F11)+N('1 Setup'!$F$10)*$F11)/$G11)+('1 Setup'!$H$10*'1 Setup'!$C$10*0.00000024*$H12)))) -> 8.9498725 | R12: =IF(OR($B12="",R11="",'1 Setup'!$C$11=""),"",IF(AND($C12="Continuous",N(INDEX('2 Phases'!$G$7:$G$12,B12))>0),IF('1 Setup'!$G$11="","",MAX(0,('1 Setup'!$G$11+('1 Setup'!$H$11*'1 Setup'!$C$11*0.00000024*$H12)/N(INDEX('2 Phases'!$G$7:$G$12,B12)))+(((R11*($G11-$F11)+N('1 Setup'!$F$11)*$F11)/$G11)-('1 Setup'!$G$11+('1 Setup'!$H$11*'1 Setup'!$C$11*0.00000024*$H12)/N(INDEX('2 Phases'!$G$7:$G$12,B12))))*EXP(-N(INDEX('2 Phases'!$G$7:$G$12,B12))))),MAX(0,((R11*($G11-$F11)+N('1 Setup'!$F$11)*$F11)/$G11)+('1 Setup'!$H$11*'1 Setup'!$C$11*0.00000024*$H12)))) -> 20.741409 | S12: =IF(OR($B12="",S11="",'1 Setup'!$C$12=""),"",IF(AND($C12="Continuous",N(INDEX('2 Phases'!$G$7:$G$12,B12))>0),IF('1 Setup'!$G$12="","",MAX(0,('1 Setup'!$G$12+('1 Setup'!$H$12*'1 Setup'!$C$12*0.00000024*$H12)/N(INDEX('2 Phases'!$G$7:$G$12,B12)))+(((S11*($G11-$F11)+N('1 Setup'!$F$12)*$F11)/$G11)-('1 Setup'!$G$12+('1 Setup'!$H$12*'1 Setup'!$C$12*0.00000024*$H12)/N(INDEX('2 Phases'!$G$7:$G$12,B12))))*EXP(-N(INDEX('2 Phases'!$G$7:$G$12,B12))))),MAX(0,((S11*($G11-$F11)+N('1 Setup'!$F$12)*$F11)/$G11)+('1 Setup'!$H$12*'1 Setup'!$C$12*0.00000024*$H12)))) | T12: =IF(OR($B12="",T11="",'1 Setup'!$C$13=""),"",IF(AND($C12="Continuous",N(INDEX('2 Phases'!$G$7:$G$12,B12))>0),IF('1 Setup'!$G$13="","",MAX(0,('1 Setup'!$G$13+('1 Setup'!$H$13*'1 Setup'!$C$13*0.00000024*$H12)/N(INDEX('2 Phases'!$G$7:$G$12,B12)))+(((T11*($G11-$F11)+N('1 Setup'!$F$13)*$F11)/$G11)-('1 Setup'!$G$13+('1 Setup'!$H$13*'1 Setup'!$C$13*0.00000024*$H12)/N(INDEX('2 Phases'!$G$7:$G$12,B12))))*EXP(-N(INDEX('2 Phases'!$G$7:$G$12,B12))))),MAX(0,((T11*($G11-$F11)+N('1 Setup'!$F$13)*$F11)/$G11)+('1 Setup'!$H$13*'1 Setup'!$C$13*0.00000024*$H12)))) | U12: =IF(OR($B12="",U11="",'1 Setup'!$C$14=""),"",IF(AND($C12="Continuous",N(INDEX('2 Phases'!$G$7:$G$12,B12))>0),IF('1 Setup'!$G$14="","",MAX(0,('1 Setup'!$G$14+('1 Setup'!$H$14*'1 Setup'!$C$14*0.00000024*$H12)/N(INDEX('2 Phases'!$G$7:$G$12,B12)))+(((U11*($G11-$F11)+N('1 Setup'!$F$14)*$F11)/$G11)-('1 Setup'!$G$14+('1 Setup'!$H$14*'1 Setup'!$C$14*0.00000024*$H12)/N(INDEX('2 Phases'!$G$7:$G$12,B12))))*EXP(-N(INDEX('2 Phases'!$G$7:$G$12,B12))))),MAX(0,((U11*($G11-$F11)+N('1 Setup'!$F$14)*$F11)/$G11)+('1 Setup'!$H$14*'1 Setup'!$C$14*0.00000024*$H12)))) | V12: =IF($B12="","",E12/1000000*'1 Setup'!$B$7) -> 14 | W12: =IF($B12="","",V12*G12) -> 14.84 | X12: =IF($B12="","",P12*'1 Setup'!$B$7/1000000000) -> 16.07202 | Y12: =IF($B12="","",L12*'1 Setup'!$B$7/1000000000) -> 8.0360098
